{"timestamp": "2025-08-20T02:13:44.304825+00:00", "level": null, "name": "flask_error_test", "message": "Error in endpoint", "exc_info": "Traceback (most recent call last):\n  File \"/home/jclee/app/blacklist/tests/test_structured_logging_flask.py\", line 218, in error_endpoint\n    raise ValueError(\"Test error for logging\")\nValueError: Test error for logging", "context": {}}
{"timestamp": "2025-08-20T03:44:19.203334+00:00", "level": null, "name": "flask_error_test", "message": "Error in endpoint", "exc_info": "Traceback (most recent call last):\n  File \"/home/jclee/app/blacklist/tests/test_structured_logging_flask.py\", line 218, in error_endpoint\n    raise ValueError(\"Test error for logging\")\nValueError: Test error for logging", "context": {}}
{"timestamp": "2025-08-20T13:00:27.258544+00:00", "level": null, "name": "flask_error_test", "message": "Error in endpoint", "exc_info": "Traceback (most recent call last):\n  File \"/home/jclee/app/blacklist/tests/test_structured_logging_flask.py\", line 218, in error_endpoint\n    raise ValueError(\"Test error for logging\")\nValueError: Test error for logging", "context": {}}
{"timestamp": "2025-08-21T01:57:04.417630+00:00", "level": null, "name": "flask_error_test", "message": "Error in endpoint", "exc_info": "Traceback (most recent call last):\n  File \"/home/jclee/app/blacklist/tests/test_structured_logging_flask.py\", line 218, in error_endpoint\n    raise ValueError(\"Test error for logging\")\nValueError: Test error for logging", "context": {}}
{"timestamp": "2025-08-21T12:45:10.713298+00:00", "level": null, "name": "flask_error_test", "message": "Error in endpoint", "exc_info": "Traceback (most recent call last):\n  File \"/home/jclee/app/blacklist/tests/test_structured_logging_flask.py\", line 215, in error_endpoint\n    raise ValueError(\"Test error for logging\")\nValueError: Test error for logging", "context": {}}
{"timestamp": "2025-08-22T00:34:55.931571+00:00", "level": null, "name": "flask_error_test", "message": "Error in endpoint", "exc_info": "Traceback (most recent call last):\n  File \"/home/jclee/app/blacklist/tests/test_structured_logging_flask.py\", line 215, in error_endpoint\n    raise ValueError(\"Test error for logging\")\nValueError: Test error for logging", "context": {}}
2025-08-22 15:35:42,690 - flask_error_test - ERROR - Error in endpoint
Traceback (most recent call last):
  File "/home/jclee/app/blacklist/tests/test_structured_logging_flask.py", line 215, in error_endpoint
    raise ValueError("Test error for logging")
ValueError: Test error for logging
{"timestamp": "2025-08-27T15:01:52.202707+00:00", "level": null, "name": "flask_error_test", "message": "Error in endpoint", "exc_info": "Traceback (most recent call last):\n  File \"/home/jclee/app/blacklist/tests/test_structured_logging_flask.py\", line 215, in error_endpoint\n    raise ValueError(\"Test error for logging\")\nValueError: Test error for logging", "context": {}}
